Workbook

Sheet LotV62
A2: THE PIT — lot V62
A3: Fichier V54 conservé. Un dessin ou une case jouable ne certifie pas un kit complet ni une fidélité 1:1.
B4: Nouveaux PNG intégrés | D4: Dessins natifs intégrés | G4: Publication
B5: =SUM(E9:E26) -> 31 | D5: =SUM(F9:F26) -> 86 | G5: Non vérifiée dans ce suivi
A6: Les icônes dérivées et les poses tenues réutilisées ne sont pas de nouveaux dessins.
A8: Chantier | B8: Élément | C8: Nature | D8: État | E8: PNG | F8: Dessins | G8: Vérification | H8: Limites | J8: Sources
A9: Combattant | B9: Emissary PHG — portrait | C9: Portrait | D9: Intégré | E9: 1 | F9: 1 | G9: Parcours Chrome V62, deux côtés, mobile et pixels natifs vérifiés. | H9: Une case distincte des deux Emissary du film. Tenue partiellement reconstruite. | J9: Emissary PHG — portrait 02_PERSONNAGES!A207:V207 / 03_MANQUANTS!A12:L12 IllFonic, mise à jour 2.39 https://forum.predator.illfonic.com/t/patch-notes-2-39/27316
A10: Combattant | B10: Emissary PHG — garde vers la droite | C10: Animation idle | D10: Intégré | E10: 1 | F10: 6 | G10: Parcours Chrome V62, deux côtés, mobile et pixels natifs vérifiés. | H10: Six dessins natifs. Déplacements et attaques non dessinés : pose tenue, pas de nouveau clip. | J10: Emissary PHG — garde vers la droite 02_PERSONNAGES!A207:V207 / 03_MANQUANTS!A12:L12 IllFonic, mise à jour 2.39 https://forum.predator.illfonic.com/t/patch-notes-2-39/27316
A11: Combattant | B11: Emissary PHG — garde vers la gauche | C11: Animation idle | D11: Intégré | E11: 1 | F11: 6 | G11: Parcours Chrome V62, deux côtés, mobile et pixels natifs vérifiés. | H11: Six dessins natifs. Déplacements et attaques non dessinés : pose tenue, pas de nouveau clip. | J11: Emissary PHG — garde vers la gauche 02_PERSONNAGES!A207:V207 / 03_MANQUANTS!A12:L12 IllFonic, mise à jour 2.39 https://forum.predator.illfonic.com/t/patch-notes-2-39/27316
A12: Identités | B12: Samurai, Emissary, Golden Angel, Classic et Captive | C12: Clarification | D12: Intégré | E12: 0 | F12: 0 | G12: Variantes, IDs, ordre et bitmaps historiques conservés. | H12: Samurai était déjà présent. Les dix dossiers nouveaux/candidats ne sont pas dix absences de case. | J12: Samurai, Emissary, Golden Angel, Classic et Captive v62-workbook-roster-audit.json / sources primaires citées
A13: Masques | B13: 14 biomasks référencés | C13: Remplacement | D13: Intégré | E13: 14 | F13: 14 | G13: 53 tests passent. Chrome :26 sélections,14 toggles,2 rechargements, aucune erreur. 28 anciens fichiers inchangés. | H13: Recréations guidées par références licenciées. Détails cachés, usure et microgravures interprétés. Pas de certification 1:1. | J13: 14 biomasks référencés BIOMASQUES-V62.md / biomask-generation-receipts.json
A14: Masques | B14: Anciens dessins préservés et renommés | C14: Conservation | D14: Intégré | E14: 0 | F14: 0 | G14: 28 fichiers historiques inchangés, empreintes vérifiées. | H14: 11 anciens V3 équipables sous IDs clan-*. Elder devient Couronne des Ancêtres. Quatre études V14 restent en galerie. Noms originaux du projet. | J14: Anciens dessins préservés et renommés BIOMASQUES-V62.md
A15: Personnage modulaire | B15: Têtes Classic, Elder, Super et Feral | C15: Remplacement | D15: Intégré | E15: 4 | F15: 4 | G15: 68 compositions DOM/Canvas contrôlées, revue visuelle représentative. Placement et teintes du rig corrigés. | H15: Quatre dessins pour six morphologies. Classic réutilisé pour Young et Huntress. Pas de nouveaux cycles faciaux. Orientation 3/4 adaptée au rig. | J15: Têtes Classic, Elder, Super et Feral modular-head-classic.json / modular-head-families.json / v62-head-composition-qa.json
A16: Arène 126 | B16: Evacuants adultes anonymes — passage lointain | C16: Animation de fond | D16: Intégré | E16: 1 | F16: 6 | G16: Chrome :3 arènes,54 cellules natives, mobile et panne503/reprise. Composition :44 caméras. Tests ciblés passés. | H16: Toit intact, ambiance d'exposition avant destruction. Evacuants adultes et appareil anonymes originaux ; aucune identité de survivant, route narrative ou continuité d'équipement de Wolf certifiée. | J16: Evacuants adultes anonymes — passage lointain 10_VIE_DES_STAGES!E62 / 10_VIE_DES_STAGES!E63 / 10_VIE_DES_STAGES!E64 arena-126-avpr-2007-hospital-roof
A17: Arène 126 | B17: Hélicoptère anonyme — rotor d'évacuation | C17: Animation de fond | D17: Intégré | E17: 1 | F17: 6 | G17: Chrome :3 arènes,54 cellules natives, mobile et panne503/reprise. Composition :44 caméras. Tests ciblés passés. | H17: Toit intact, ambiance d'exposition avant destruction. Evacuants adultes et appareil anonymes originaux ; aucune identité de survivant, route narrative ou continuité d'équipement de Wolf certifiée. | J17: Hélicoptère anonyme — rotor d'évacuation 10_VIE_DES_STAGES!E62 / 10_VIE_DES_STAGES!E63 / 10_VIE_DES_STAGES!E64 arena-126-avpr-2007-hospital-roof
A18: Arène 126 | B18: Évent de toiture — vapeur dans le vent | C18: Animation de fond | D18: Intégré | E18: 1 | F18: 6 | G18: Chrome :3 arènes,54 cellules natives, mobile et panne503/reprise. Composition :44 caméras. Tests ciblés passés. | H18: Toit intact, ambiance d'exposition avant destruction. Evacuants adultes et appareil anonymes originaux ; aucune identité de survivant, route narrative ou continuité d'équipement de Wolf certifiée. | J18: Évent de toiture — vapeur dans le vent 10_VIE_DES_STAGES!E62 / 10_VIE_DES_STAGES!E63 / 10_VIE_DES_STAGES!E64 arena-126-avpr-2007-hospital-roof
A19: Arène 130 | B19: Marine anonyme — traversée de passerelle | C19: Animation de fond | D19: Intégré | E19: 1 | F19: 6 | G19: Chrome :3 arènes,54 cellules natives, mobile et panne503/reprise. Composition :44 caméras. Tests ciblés passés. | H19: Adaptation d'exposition de station industrielle. Marine adulte anonyme et mécanismes originaux ; ni héros Classic 2000 ni route scénarisée ou niveau exact certifié. | J19: Marine anonyme — traversée de passerelle 10_VIE_DES_STAGES!E143 / 10_VIE_DES_STAGES!E144 / 10_VIE_DES_STAGES!E145 arena-130-avp-classic-2000-space-station
A20: Arène 130 | B20: Ascenseur de service — cycle de porte | C20: Animation de fond | D20: Intégré | E20: 1 | F20: 6 | G20: Chrome :3 arènes,54 cellules natives, mobile et panne503/reprise. Composition :44 caméras. Tests ciblés passés. | H20: Adaptation d'exposition de station industrielle. Marine adulte anonyme et mécanismes originaux ; ni héros Classic 2000 ni route scénarisée ou niveau exact certifié. | J20: Ascenseur de service — cycle de porte 10_VIE_DES_STAGES!E143 / 10_VIE_DES_STAGES!E144 / 10_VIE_DES_STAGES!E145 arena-130-avp-classic-2000-space-station
... A26: Arène 051 | B26: Cataractes des Anciens | C26: Conservation | D26: Intégré | E26: 0 | F26: 0 | G26: Ancien ID jouable et images conservés, sans migration forcée des sauvegardes. | H26: Ancienne ruine à cascades renommée création originale. Elle ne représente plus Camp Golgotha. | J26: Cataractes des Anciens v62-golgotha-reconciliation.json

Sheet CombattantsV54
A2: Combattants — 205 dossiers V54
A3: Correspondances du classeur. Les trois créations utilisateur V56 hors V54 restent également jouables.
B4: Dossiers reliés au roster | D4: Identité ou apparence ouverte | F4: Cases runtime
B5: =COUNTIF(C9:C213,"Oui") -> 199 | D5: =COUNTIF(C9:C213,"Non") -> 6 | F5: 199
A6: 199 dossiers reliés, 199 cases runtime : populations distinctes. Six dossiers restent ouverts.
A8: ID V54 | B8: Nom du dossier | C8: Jouable | D8: ID en jeu | E8: Variantes | F8: État | G8: Kit natif complet | H8: Constat | I8: Cellules V54
A9: jungle-hunter | B9: Jungle Hunter | C9: Oui | D9: jungle-hunter | E9: 14 | F9: Déjà au roster | G9: Non certifié | H9: Présence dans le roster seulement ; ni kit complet ni fidélité 1:1 ne sont déduits de cette correspondance. | I9: 02_PERSONNAGES!A5:V5
A10: city-hunter | B10: City Hunter | C10: Oui | D10: city-hunter | E10: 13 | F10: Déjà au roster | G10: Non certifié | H10: Présence dans le roster seulement ; ni kit complet ni fidélité 1:1 ne sont déduits de cette correspondance. | I10: 02_PERSONNAGES!A6:V6
A11: scar | B11: Scar | C11: Oui | D11: scar | E11: 5 | F11: Déjà au roster | G11: Non certifié | H11: Présence dans le roster seulement ; ni kit complet ni fidélité 1:1 ne sont déduits de cette correspondance. | I11: 02_PERSONNAGES!A7:V7
A12: celtic | B12: Celtic | C12: Oui | D12: celtic | E12: 4 | F12: Déjà au roster | G12: Non certifié | H12: Présence dans le roster seulement ; ni kit complet ni fidélité 1:1 ne sont déduits de cette correspondance. | I12: 02_PERSONNAGES!A8:V8
A13: wolf | B13: Wolf | C13: Oui | D13: wolf | E13: 5 | F13: Déjà au roster | G13: Non certifié | H13: Présence dans le roster seulement ; ni kit complet ni fidélité 1:1 ne sont déduits de cette correspondance. | I13: 02_PERSONNAGES!A9:V9
A14: feral-hunter | B14: Feral | C14: Oui | D14: feral-hunter | E14: 7 | F14: Déjà au roster | G14: Non certifié | H14: Présence dans le roster seulement ; ni kit complet ni fidélité 1:1 ne sont déduits de cette correspondance. | I14: 02_PERSONNAGES!A10:V10
A15: berserker | B15: Berserker / Mr. Black | C15: Oui | D15: berserker | E15: 4 | F15: Déjà au roster | G15: Non certifié | H15: Présence dans le roster seulement ; ni kit complet ni fidélité 1:1 ne sont déduits de cette correspondance. | I15: 02_PERSONNAGES!A11:V11
A16: falconer | B16: Falconer | C16: Oui | D16: falconer | E16: 4 | F16: Déjà au roster | G16: Non certifié | H16: Présence dans le roster seulement ; ni kit complet ni fidélité 1:1 ne sont déduits de cette correspondance. | I16: 02_PERSONNAGES!A12:V12
A17: scarface | B17: Scarface | C17: Oui | D17: scarface | E17: 2 | F17: Déjà au roster | G17: Non certifié | H17: Présence dans le roster seulement ; ni kit complet ni fidélité 1:1 ne sont déduits de cette correspondance. | I17: 02_PERSONNAGES!A13:V13
A18: valkyrie | B18: Valkyrie | C18: Oui | D18: valkyrie | E18: 4 | F18: Déjà au roster | G18: Non certifié | H18: Présence dans le roster seulement ; ni kit complet ni fidélité 1:1 ne sont déduits de cette correspondance. | I18: 02_PERSONNAGES!A14:V14
A19: witch | B19: Witch | C19: Oui | D19: witch | E19: 2 | F19: Déjà au roster | G19: Non certifié | H19: Présence dans le roster seulement ; ni kit complet ni fidélité 1:1 ne sont déduits de cette correspondance. | I19: 02_PERSONNAGES!A15:V15
A20: enforcer | B20: Enforcer | C20: Oui | D20: enforcer | E20: 2 | F20: Déjà au roster | G20: Non certifié | H20: Présence dans le roster seulement ; ni kit complet ni fidélité 1:1 ne sont déduits de cette correspondance. | I20: 02_PERSONNAGES!A16:V16
... A213: variant-samurai-phg | B213: Samurai — Hunting Grounds | C213: Oui | D213: user-samurai | E213: 2 | F213: Déjà présent, clarifié | G213: Non certifié | H213: Deux apparences NECA Hunting Grounds déjà présentes ; identité précisée en V62 sans nouvelle case. Kit natif complet toujours non livré. | I213: 02_PERSONNAGES!A209:V209

Sheet Resteclasseur
A2: Demandes encore ouvertes — suivi V63
A3: Distinguer absence, apparence intégrée, kit partiel et conditions narratives encore non vérifiées.
A5: Les 522 demandes restent suivies ; six adaptations V63 ne certifient pas tous les événements.
A8: Chantier | B8: Dossier ou demande | C8: État | D8: Suite nécessaire | E8: Source
A9: Combattant | B9: Predator du tournoi — Bloodshed | C9: Identité ou apparence ouverte | D9: Identité du tournoi attestée par Marvel ; apparence native et kit jouable manquants. Les dessins anonymes fournis ne permettent pas une attribution certaine. | E9: 02_PERSONNAGES!A200:V200 / 03_MANQUANTS!A5:L5
A10: Combattant | B10: Super Predator — The Last Hunt | C10: Identité ou apparence ouverte | D10: Dossier distinct de Mr. Black. Référence de tenue et arsenal à verrouiller ; aucun ajout par simple renommage. | E10: 02_PERSONNAGES!A201:V201 / 03_MANQUANTS!A6:L6
A11: Combattant | B11: Predator jouable — AVP Jaguar | C11: Identité ou apparence ouverte | D11: Incarnation AVP Jaguar absente ; ne pas substituer Dark, Prince ou Jungle Hunter. | E11: 02_PERSONNAGES!A202:V202 / 03_MANQUANTS!A7:L7
A12: Combattant | B12: Predator jouable — AVP Classic 2000 | C12: Identité ou apparence ouverte | D12: Incarnation AVP Classic 2000 absente ; user-classic-2010 appartient au film Predators. | E12: 02_PERSONNAGES!A203:V203 / 03_MANQUANTS!A8:L8
A13: Combattant | B13: Predator père — Blood Ties | C13: Identité ou apparence ouverte | D13: Père de Blood Ties : attribution visuelle à établir avant création ou réaffectation. | E13: 02_PERSONNAGES!A204:V204 / 03_MANQUANTS!A9:L9
A14: Combattant | B14: Predator fils — Blood Ties | C14: Identité ou apparence ouverte | D14: Fils de Blood Ties : identité distincte à établir, sans fusion avec les cycles I et II. | E14: 02_PERSONNAGES!A205:V205 / 03_MANQUANTS!A10:L10
A15: Animations combattants | B15: Emissary, Elder, Captured PHG et bibliothèques incomplètes | C15: Kit partiel | D15: Les trois apparences ont des gardes natives, mais les mouvements, attaques, réactions, intros et résultats de manche restent à dessiner. Aucun kit complet ni dix plaquettes par personnage certifié. | E15: 02_PERSONNAGES / exigences animation V54
A16: Arène 126 | B16: Toit de l’hôpital · variante narrative | C16: Ambiance ajoutée, chapitre ouvert | D16: E62 : évacuation conservée mais inactive sur le toit sans civils. Produire une continuité hors toit cohérente ; route, chronologie et équipement de Wolf restent ouverts. | E16: 09_STAGES!A24:N24
A17: Arène 51 | B17: Camp Golgotha — nouvelle arène 187 | C17: Ambiance ajoutée, chapitre ouvert | D17: V62 fournit un triplet d’ambiance d’exposition. Le chapitre, sa route, ses personnages et ses conditions exactes restent à intégrer. Marines derrière un sas Capteur d’alarme lent Xénomorphe derrière un vitrage distant | E17: 09_STAGES!A50:N50
A18: Arène 130 | B18: Station orbitale Classic | C18: Ambiance ajoutée, chapitre ouvert | D18: V62 fournit un triplet d’ambiance d’exposition. Le chapitre, sa route, ses personnages et ses conditions exactes restent à intégrer. Marine en fuite par une passerelle Porte d’ascenseur hors zone jouable Lumière de quarantaine à intensité bornée | E18: 09_STAGES!A51:N51
A19: Arène 119 | B19: Gorge de la planète hostile | C19: À réaliser | D19: Variante de cadrage/scénario de Dek autour d’un monde existant. Thia observant depuis un abri seulement dans les chapitres alliés Faune extraterrestre dont l’espèce et l’échelle seront référencées Végétation hostile en arrière-plan sans collision compétitive | E19: 09_STAGES!A54:N54
... A36: Homeworld | B36: Refonte de la ville en 2.5D | C36: Nouvelle demande, non livrée V63 | D36: Unifier caméra, maisons, portes, intérieurs, spatioport, proportions et codex des dimensions. V63 ne certifie pas cette future refonte. | E36: Demande utilisateur reçue après le lot V63

Sheet LotV63
A2: THE PIT — changements du lot V63
A3: Copie du suivi V62 ; onglet LotV62 conservé comme historique. Source V54 inchangée.
B4: Nouveaux PNG intégrés | D4: Dessins natifs intégrés | G4: Publication V63
B5: =SUM(E9:E26) -> 13 | D5: =SUM(F9:F26) -> 63 | G5: Non vérifiée dans ce suivi
A6: Deux apparences, zéro nouvelle case ; quatre gardes ne constituent pas deux kits complets.
A8: Chantier | B8: Élément | C8: Nature | D8: État | E8: PNG | F8: Dessins | G8: Vérification | H8: Limites | J8: Sources
A9: Combattant | B9: Hunting Grounds · Elder sans masque · garde native · portrait | C9: Portrait | D9: Intégré, kit partiel | E9: 1 | F9: 1 | G9: Chrome : deux sens, six poses natives par garde ; mobile paysage, pause et sélection vérifiés. | H9: Variante sur une case existante. Marche, attaque, intro et résultats restent à produire. Détails cachés reconstruits, sans certification 1:1. | J9: 02_PERSONNAGES!A206:V206 / 03_MANQUANTS!A11:L11 https://blog.playstation.com/2020/06/12/june-free-update-now-live-in-predator-hunting-grounds/ https://live.staticflickr.com/65535/49996764556_c03bc385e7_h.jpg
A10: Combattant | B10: Hunting Grounds · Elder sans masque · garde native · idle-right | C10: Garde animée | D10: Intégré, kit partiel | E10: 1 | F10: 6 | G10: Chrome : deux sens, six poses natives par garde ; mobile paysage, pause et sélection vérifiés. | H10: Variante sur une case existante. Marche, attaque, intro et résultats restent à produire. Détails cachés reconstruits, sans certification 1:1. | J10: 02_PERSONNAGES!A206:V206 / 03_MANQUANTS!A11:L11 https://blog.playstation.com/2020/06/12/june-free-update-now-live-in-predator-hunting-grounds/ https://live.staticflickr.com/65535/49996764556_c03bc385e7_h.jpg
A11: Combattant | B11: Hunting Grounds · Elder sans masque · garde native · idle-left | C11: Garde animée | D11: Intégré, kit partiel | E11: 1 | F11: 6 | G11: Chrome : deux sens, six poses natives par garde ; mobile paysage, pause et sélection vérifiés. | H11: Variante sur une case existante. Marche, attaque, intro et résultats restent à produire. Détails cachés reconstruits, sans certification 1:1. | J11: 02_PERSONNAGES!A206:V206 / 03_MANQUANTS!A11:L11 https://blog.playstation.com/2020/06/12/june-free-update-now-live-in-predator-hunting-grounds/ https://live.staticflickr.com/65535/49996764556_c03bc385e7_h.jpg
A12: Combattant | B12: Hunting Grounds · Captured masqué · garde native · portrait | C12: Portrait | D12: Intégré, kit partiel | E12: 1 | F12: 1 | G12: Chrome : deux sens, six poses natives par garde ; mobile paysage, pause et sélection vérifiés. | H12: Variante sur une case existante. Marche, attaque, intro et résultats restent à produire. Détails cachés reconstruits, sans certification 1:1. | J12: 02_PERSONNAGES!A208:V208 / 03_MANQUANTS!A13:L13 https://blog.playstation.com/2021/12/15/predator-hunting-grounds-introduces-the-hunting-party/ https://store.steampowered.com/app/1847080/Predator_Hunting_Grounds__Hunting_Party_Bundle/ https://shared.akamai.steamstatic.com/store_item_assets/steam/apps/1847080/ss_4ebbc1badb9563972092231cb1e41b357a7de04e.1920x1080.jpg?t=1764097265
A13: Combattant | B13: Hunting Grounds · Captured masqué · garde native · idle-right | C13: Garde animée | D13: Intégré, kit partiel | E13: 1 | F13: 6 | G13: Chrome : deux sens, six poses natives par garde ; mobile paysage, pause et sélection vérifiés. | H13: Variante sur une case existante. Marche, attaque, intro et résultats restent à produire. Détails cachés reconstruits, sans certification 1:1. | J13: 02_PERSONNAGES!A208:V208 / 03_MANQUANTS!A13:L13 https://blog.playstation.com/2021/12/15/predator-hunting-grounds-introduces-the-hunting-party/ https://store.steampowered.com/app/1847080/Predator_Hunting_Grounds__Hunting_Party_Bundle/ https://shared.akamai.steamstatic.com/store_item_assets/steam/apps/1847080/ss_4ebbc1badb9563972092231cb1e41b357a7de04e.1920x1080.jpg?t=1764097265
A14: Combattant | B14: Hunting Grounds · Captured masqué · garde native · idle-left | C14: Garde animée | D14: Intégré, kit partiel | E14: 1 | F14: 6 | G14: Chrome : deux sens, six poses natives par garde ; mobile paysage, pause et sélection vérifiés. | H14: Variante sur une case existante. Marche, attaque, intro et résultats restent à produire. Détails cachés reconstruits, sans certification 1:1. | J14: 02_PERSONNAGES!A208:V208 / 03_MANQUANTS!A13:L13 https://blog.playstation.com/2021/12/15/predator-hunting-grounds-introduces-the-hunting-party/ https://store.steampowered.com/app/1847080/Predator_Hunting_Grounds__Hunting_Party_Bundle/ https://shared.akamai.steamstatic.com/store_item_assets/steam/apps/1847080/ss_4ebbc1badb9563972092231cb1e41b357a7de04e.1920x1080.jpg?t=1764097265
A15: Arène 126 | B15: Gaine vibrante — raccord fixé au bloc HVAC | C15: Animation de fond | D15: Adaptation intégrée | E15: 1 | F15: 6 | G15: Rendu et application vérifiés ; voir preuve finale liée. | H15: Six poses ; ambiance adaptée. Aucun chapitre ni fidélité littérale 1:1 certifiés. | J15: 10_VIE_DES_STAGES!E503 arena-126-avpr-2007-hospital-roof
A16: Arène 126 | B16: Lumières urbaines — variation lente distante | C16: Animation de fond | D16: Adaptation intégrée | E16: 1 | F16: 6 | G16: Rendu et application vérifiés ; voir preuve finale liée. | H16: Six poses ; ambiance adaptée. Aucun chapitre ni fidélité littérale 1:1 certifiés. | J16: 10_VIE_DES_STAGES!E504 arena-126-avpr-2007-hospital-roof
A17: Arène 126 | B17: Panache avant destruction — cheminée de fond | C17: Animation de fond | D17: Adaptation intégrée | E17: 1 | F17: 6 | G17: Rendu et application vérifiés ; voir preuve finale liée. | H17: Six poses ; ambiance adaptée. Aucun chapitre ni fidélité littérale 1:1 certifiés. | J17: 10_VIE_DES_STAGES!E505 arena-126-avpr-2007-hospital-roof
A18: Arène 130 | B18: Piston de maintenance — derrière barrière | C18: Animation de fond | D18: Adaptation intégrée | E18: 1 | F18: 6 | G18: Rendu et application vérifiés ; voir preuve finale liée. | H18: Six poses ; ambiance adaptée. Aucun chapitre ni fidélité littérale 1:1 certifiés. | J18: 10_VIE_DES_STAGES!E512 arena-130-avp-classic-2000-space-station
A19: Arène 130 | B19: Purge intermittente — conduite du fond | C19: Animation de fond | D19: Adaptation intégrée | E19: 1 | F19: 6 | G19: Rendu et application vérifiés ; voir preuve finale liée. | H19: Six poses ; ambiance adaptée. Aucun chapitre ni fidélité littérale 1:1 certifiés. | J19: 10_VIE_DES_STAGES!E513 arena-130-avp-classic-2000-space-station
A20: Arène 130 | B20: Trappe de contrôle — voyant ambre stable | C20: Animation de fond | D20: Adaptation intégrée | E20: 1 | F20: 6 | G20: Rendu et application vérifiés ; voir preuve finale liée. | H20: Six poses ; ambiance adaptée. Aucun chapitre ni fidélité littérale 1:1 certifiés. | J20: 10_VIE_DES_STAGES!E514 arena-130-avp-classic-2000-space-station
... A26: Menu et sauvegardes | B26: Nouvelle partie, remplacement et récupération | C26: Parcours corrigé | D26: Intégré | E26: 0 | F26: 0 | G26: 91 tests ciblés ; 12 scénarios Chrome isolés. | H26: Aucune sauvegarde personnelle utilisée. Publication distincte du contrôle local. | J26: docs/V63-MENU-SAUVEGARDES.md / docs/v63-menu-after-qa.json

Sheet StagesV54
A2: 174 dossiers de stages — correspondances et demandes V54
A3: 170 cibles de décor ; 522 descriptions conservées. Présence runtime et fidélité littérale sont deux contrôles distincts.
B4: Dossiers sans registre natif V60–V63 | D4: Sans décor runtime | F4: Cibles distinctes avec registre | H4: Événements actifs sur les 35 cibles distinctes
B5: =COUNTIF(E9:E182,0) -> 136 | D5: =COUNTIF(D9:D182,"Non") -> 0 | F5: 35 | H5: 110
A6: Un registre absent ne prouve pas l’absence de tout effet hérité. Les doublons ne doivent pas être additionnés comme nouveaux dessins.
A8: ID V54 | B8: Stage demandé | C8: ID runtime | D8: Décor résolu | E8: Événements natifs | F8: Registre | G8: Dossier complet | H8: Trois demandes et statut | J8: Cellules source
A9: ST001 | B9: Clairière des pièges | C9: arena-103-predator-1987-final-trap-clearing | D9: Oui | E9: 0 | F9: Registre V60–V63 absent | G9: Non certifié | H9: 10_VIE_DES_STAGES!E5 Feuilles secouées par une fuite d’oiseaux Non recertifié par V63 10_VIE_DES_STAGES!E6 Insectes en lisière, jamais devant les silhouettes Non recertifié par V63 10_VIE_DES_STAGES!E7 Lointaine patrouille armée avant le duel, absente du face-à-face final Non recertifié par V63 | J9: 09_STAGES!A5:N5
A10: ST002 | B10: Vaisseau des trophées | C10: arena-106-predator-2-1990-trophy-ship | D10: Oui | E10: 0 | F10: Registre V60–V63 absent | G10: Non certifié | H10: 10_VIE_DES_STAGES!E8 Membres anonymes du clan observant sans intervenir Non recertifié par V63 10_VIE_DES_STAGES!E9 Éclairage de niches passant doucement d’un trophée à l’autre Non recertifié par V63 10_VIE_DES_STAGES!E10 Ouverture furtive de la rampe et vapeur basse Non recertifié par V63 | J10: 09_STAGES!A6:N6
A11: ST003 | B11: Chambre sacrificielle | C11: arena-122-avp-2004-sacrificial-chamber | D11: Oui | E11: 0 | F11: Registre V60–V63 absent | G11: Non certifié | H11: 10_VIE_DES_STAGES!E11 Ombre de xénomorphe derrière une grille Non recertifié par V63 10_VIE_DES_STAGES!E12 Hologramme du labyrinthe sur un socle Non recertifié par V63 10_VIE_DES_STAGES!E13 Vapeur froide et poussière aux joints des murs Non recertifié par V63 | J11: 09_STAGES!A7:N7
A12: ST004 | B12: Épave de Gunnison | C12: arena-127-avpr-2007-forest-crash | D12: Oui | E12: 0 | F12: Registre V60–V63 absent | G12: Non certifié | H12: 10_VIE_DES_STAGES!E14 Balise endommagée clignotant lentement Non recertifié par V63 10_VIE_DES_STAGES!E15 Silhouette xénomorphe traversant une brèche éloignée Non recertifié par V63 10_VIE_DES_STAGES!E16 Braises et fumée verticale non opaque Non recertifié par V63 | J12: 09_STAGES!A8:N8
A13: ST005 | B13: Camp de la réserve | C13: arena-107-predators-2010-hunting-camp | D13: Oui | E13: 0 | F13: Registre V60–V63 absent | G13: Non certifié | H13: 10_VIE_DES_STAGES!E17 Predator Hound reniflant derrière une barrière hors combat Non recertifié par V63 10_VIE_DES_STAGES!E18 Drone de reconnaissance lointain sans cible HUD Non recertifié par V63 10_VIE_DES_STAGES!E19 Végétation qui bouge à l’approche d’une proie cachée Non recertifié par V63 | J13: 09_STAGES!A9:N9
A14: ST006 | B14: Bourbier | C14: arena-115-prey-2022-mud-pit | D14: Oui | E14: 0 | F14: Registre V60–V63 absent | G14: Non certifié | H14: 10_VIE_DES_STAGES!E20 Oiseaux quittant les roseaux Non recertifié par V63 10_VIE_DES_STAGES!E21 Bison lointain en variante de plaine seulement, pas dans chaque forêt Non recertifié par V63 10_VIE_DES_STAGES!E22 Trappeur adulte repliant un piège avant de fuir, non complice de Feral Non recertifié par V63 | J14: 09_STAGES!A10:N10
A15: ST007 | B15: Crash de la forêt | C15: arena-112-the-predator-2018-forest-crash | D15: Oui | E15: 0 | F15: Registre V60–V63 absent | G15: Non certifié | H15: 10_VIE_DES_STAGES!E23 Chien extraterrestre derrière la coque, sans dégâts Non recertifié par V63 10_VIE_DES_STAGES!E24 Agent Stargazer inspectant un écran puis se mettant à couvert Non recertifié par V63 10_VIE_DES_STAGES!E25 Ventilation d’une capsule endommagée Non recertifié par V63 | J15: 09_STAGES!A11:N11
A16: ST008 | B16: Cour du clan | C16: arena-121-badlands-2025-clan-prologue | D16: Oui | E16: 0 | F16: Registre V60–V63 absent | G16: Non certifié | H16: 10_VIE_DES_STAGES!E26 Gardes adultes immobiles puis échange de regard Non recertifié par V63 10_VIE_DES_STAGES!E27 Portes monumentales se fermant avant le round Non recertifié par V63 10_VIE_DES_STAGES!E28 Feux rituels et bannières limitées aux références visuelles Non recertifié par V63 | J16: 09_STAGES!A12:N12
A17: ST009 | B17: Arène du Warlord | C17: arena-118-killer-of-killers-2025-yautja-arena | D17: Oui | E17: 0 | F17: Registre V60–V63 absent | G17: Non certifié | H17: 10_VIE_DES_STAGES!E29 Spectateurs yautja se penchant au bord des gradins Non recertifié par V63 10_VIE_DES_STAGES!E30 Garde refermant une cellule de combattant Non recertifié par V63 10_VIE_DES_STAGES!E31 Signal mécanique du début de duel Non recertifié par V63 | J17: 09_STAGES!A13:N13
A18: ST010 | B18: Glace du récit The Shield | C18: arena-116-killer-of-killers-2025-viking-ice | D18: Oui | E18: 0 | F18: Registre V60–V63 absent | G18: Non certifié | H18: 10_VIE_DES_STAGES!E32 Survivants adultes cherchant un abri au loin Non recertifié par V63 10_VIE_DES_STAGES!E33 Neige tombant d’une branche après un coup lourd Non recertifié par V63 10_VIE_DES_STAGES!E34 Glaçons détachés derrière le plan de jeu Non recertifié par V63 | J18: 09_STAGES!A14:N14
A19: ST011 | B19: Toits du récit The Sword | C19: arena-117-killer-of-killers-2025-japan-rooftops | D19: Oui | E19: 0 | F19: Registre V60–V63 absent | G19: Non certifié | H19: 10_VIE_DES_STAGES!E35 Garde regardant depuis une galerie éloignée Non recertifié par V63 10_VIE_DES_STAGES!E36 Lanternes à faible amplitude Non recertifié par V63 10_VIE_DES_STAGES!E37 Tuiles et poussière uniquement derrière les pieds Non recertifié par V63 | J19: 09_STAGES!A15:N15
A20: ST012 | B20: Freya’s Prospect | C20: arena-131-avp-2010-freyas-prospect | D20: Oui | E20: 0 | F20: Registre V60–V63 absent | G20: Non certifié | H20: 10_VIE_DES_STAGES!E38 Marines en repli derrière une porte blindée Non recertifié par V63 10_VIE_DES_STAGES!E39 Xénomorphe parcourant une canalisation extérieure Non recertifié par V63 10_VIE_DES_STAGES!E40 Écran de quarantaine et gyrophares lents Non recertifié par V63 | J20: 09_STAGES!A16:N16
... A182: ST174 | B182: Predator hunting grounds airstrip | C182: arena-136-predator-hunting-grounds-airstrip | D182: Oui | E182: 0 | F182: Registre V60–V63 absent | G182: Non certifié | H182: 10_VIE_DES_STAGES!E524 Atmosphère locale derrière la zone de combat Non recertifié par V63 10_VIE_DES_STAGES!E525 Mouvement d'un élément mécanique ou végétal attesté par le décor Non recertifié par V63 10_VIE_DES_STAGES!E526 Silhouette de fond uniquement après validation de sa présence dans la scène Non recertifié par V63 | J182: 09_STAGES!A178:N178

Sheet SyntheseV99
A1: YAUTJA · suivi consolidé V99
A2: Arrêté au 2026-10-20 · données runtime actuelles, preuves et travaux ouverts distingués
A3: Synthèse : SyntheseV99 · filtres ligne 4 · en-têtes figés
A4: Indicateur | B4: Valeur | C4: Portée / limite
A5: Chantiers suivis | B5: =COUNTA('ChantiersV99'!A5:A24) -> 20 | C5: Des livraisons partielles et des travaux ouverts, pas un pourcentage de jeu terminé.
A6: EN_COURS | B6: =COUNTIF('ChantiersV99'!F5:F24,"EN_COURS") -> 0 | C6: Statut explicite du registre ; modifier le statut du chantier actualise le compteur Excel.
A7: A_VALIDER | B7: =COUNTIF('ChantiersV99'!F5:F24,"A_VALIDER") -> 0 | C7: Statut explicite du registre ; modifier le statut du chantier actualise le compteur Excel.
A8: OUVERT | B8: =COUNTIF('ChantiersV99'!F5:F24,"OUVERT") -> 9 | C8: Statut explicite du registre ; modifier le statut du chantier actualise le compteur Excel.
A9: LIVRE_PARTIEL | B9: =COUNTIF('ChantiersV99'!F5:F24,"LIVRE_PARTIEL") -> 6 | C9: Statut explicite du registre ; modifier le statut du chantier actualise le compteur Excel.
A10: VALIDE_CIBLE | B10: =COUNTIF('ChantiersV99'!F5:F24,"VALIDE_CIBLE") -> 5 | C10: Statut explicite du registre ; modifier le statut du chantier actualise le compteur Excel.
A11: Planètes dans le runtime | B11: =COUNTA('PlanetesV99'!A5:A34) -> 30 | C11: Cartes du projet ; Korthas reprend ses noms et règles V3.
A12: Biomes classiques | B12: =COUNTIF('PlanetesV99'!C5:C34,"classic") -> 16 | C12: Direction artistique classique ; pas une certification canonique 1:1.
A13: Biomes exotiques | B13: =COUNTIF('PlanetesV99'!C5:C34,"exotic") -> 14 | C13: Surfaces originales du projet, non jouables entre les terres.
A14: Ouvrages source V6 | B14: =COUNTA('OuvragesV6'!A5:A22) -> 18 | C14: Une ligne par W3-S01 à W3-S18.
A15: Ouvrages acceptés en contexte libre | B15: =COUNTIF('OuvragesV6'!F5:F22,"INTEGRE_LIBRE") -> 12 | C15: Exports actuels ; campagne et tests restent des dimensions séparées.
A16: Ouvrages restant ouverts | B16: =COUNTIF('OuvragesV6'!F5:F22,"OUVERT") -> 6 | C16: Transport, montures, énergie, duel, sons situés et route orbitale.
A17: Fiches V3 embarquées | B17: 679 | C17: 32 feuilles contenant des fiches dans l'export runtime ; original annoncé à 39 feuilles par l'import V85, pas autant de fonctionnalités jouées.
A18: Fiches guerre V6 embarquées | B18: 975 | C18: 33 feuilles extraites ; la source privée comprend davantage de domaines.
A19: Scènes documentaires | B19: 730 | C19: 6059 répliques, 1494 choix, 150 variantes, 400 réactions ; pas autant de missions incarnées.
A20: Directions de voix textuelles | B20: 210 | C20: 202 noms distincts / 8 noms ambigus ; aucun nouvel enregistrement audio dans ce lot.
A21: Feuilles du corpus navire | B21: 19 | C21: Corpus consultable ; inspection, acquisition et voyage ne sont pas le même état.
A22: Identifiants combattants runtime actuels | B22: 201 | C22: Population distincte des 205 dossiers historiques du classeur V54.
A23: Arènes runtime actuelles | B23: 187 | C23: Un décor disponible ne certifie pas les événements littéraux du dossier source.
A24: Dossiers personnages V54 ouverts en V63 | B24: 6 | C24: État historique repris explicitement ; pas recertifié V99.
A25: Descriptions de vie des stages conservées | B25: 522 | C25: 174 dossiers historiques ; leurs cellules et statuts V63 restent visibles.
A26: Dossiers stages littéralement certifiés par V99 | B26: 0 | C26: Aucune certification intégrale nouvelle de ces dossiers.
A27: Originaux privés présents | B27: 0 | C27: Les extractions et leurs empreintes sont conservées ; aucun original privé n’a été recréé.
A28: Application Excel native vérifiée | B28: NON | C28: Vérification ZIP/XML et lecture indépendante ; Excel/LibreOffice natif non lancé.

Sheet ChantiersV99
A1: Sources → implémentation → preuve → reste
A2: Une livraison partielle, un test ciblé et une validation navigateur ont leur propre portée.
A3: Synthèse : SyntheseV99 · filtres ligne 4 · en-têtes figés
A4: ID | B4: Domaine | C4: Chantier | D4: Source / cellules | E4: Implémentation | F4: Statut chantier | G4: Comportement / portée | H4: Tests | I4: Navigateur | J4: Preuves / commandes | K4: Reste à faire | L4: Responsable
A5: CLANS-V99-GARRISONS | B5: Guerre de clans | C5: Affecter et libérer une garnison existante | D5: V3 : Règles de conquête, CON-R08 ligne 13 ; CON-R12 ligne 17 ; CON-R15 ligne 20 | E5: app/game/systems/clanWarV85.ts app/game/ClanWarGarrisonV99.tsx | F5: VALIDE_CIBLE | G5: Affectation locale de personnes existantes ; refus réservé / blessé / mort / formation ; confirmation du dernier garde. | H5: PASS 101/101 ciblés ; dont 11 V99 + 4 revue | I5: PASS_PRODUCTION 26/26 ; pilote renforcé | J5: tests/clan-war-garrison-v99.test.mjs docs/clan-war-garrison-v99.md tests/clan-war-garrison-review-v99.test.mjs outputs/qa-three-modes-v99/production/result.json | K5: Modèle, SSR, régressions et Chromium production (26/26 avec pilote renforcé) validés. Portée limitée aux garnisons existantes ; les règles V3 globales et la campagne restent ouvertes. Publication suivie séparément. | L5: clans_v99
A6: PRESERVE-V99-DEPOTS | B6: Preserve Hunt | C6: Neutraliser un lot dans un dépôt physique | D6: Prolongement original V66/V98 ; demande Répartition des joueurs Predator 6aa9eb58-e760-83eb-8098-e735f1d01161 | E6: app/game/systems/gameReserveV66.ts app/game/GameReserveTacticalV98.tsx | F6: VALIDE_CIBLE | G6: Interaction sur place pendant 2 s ; le lot identifié du dépôt est concerné. | H6: PASS 40/40 ciblés ; 26 régressions + 9 V99 + 5 revue | I6: PASS_PRODUCTION 26/26 ; pilote renforcé | J6: tests/game-reserve-supply-denial-v99.test.mjs docs/v99-preserve-hunt-supply-denial.md tests/game-reserve-logistics-review-v99.test.mjs outputs/qa-three-modes-v99/production/result.json | K6: Modèle, interface, persistance et Chromium production (26/26 avec pilote renforcé) validés. Le terrain reste 3/80 secteurs et 8/100 combattants ; aucun nouvel asset, animation ou lore canonique. Publication suivie séparément. | L6: preserve_v99
A7: PRESERVE-V99-RECUPERATION | B7: Preserve Hunt | C7: Récupérer à pied un porteur abattu | D7: Prolongement original de docs/v66-game-reserve-delivery.md et docs/v98-preserve-hunt-interceptions.md | E7: app/game/systems/gameReserveV66.ts app/game/GameReserveTacticalV98.tsx | F7: VALIDE_CIBLE | G7: Un survivant proche se déplace réellement vers les composants du porteur abattu. | H7: PASS 40/40 ciblés ; 26 régressions + 9 V99 + 5 revue | I7: PASS_PRODUCTION 26/26 ; pilote renforcé | J7: tests/game-reserve-supply-denial-v99.test.mjs docs/v99-preserve-hunt-supply-denial.md tests/game-reserve-logistics-review-v99.test.mjs outputs/qa-three-modes-v99/production/result.json | K7: Modèle, interface, persistance et Chromium production (26/26 avec pilote renforcé) validés. Le terrain reste 3/80 secteurs et 8/100 combattants ; aucun nouvel asset, animation ou lore canonique. Publication suivie séparément. | L7: preserve_v99
A8: HW-NAV-PERF | B8: Homeworld | C8: Réduire le calcul froid et les points du guidage | D8: Prolongement de docs/homeworld-wayfinding-v98.md ; navigation du projet, pas nouvelle source canonique | E8: app/game/systems/homeworldNavigationV99.ts app/game/systems/homeworldWayfindingV98.ts | F8: VALIDE_CIBLE | G8: Hiérarchie A* et repli V77 implémentés ; froid 11 297 → 3 190 ms (×3,54), premier palier 183 → 18 points ; longueur totale +7,6 %. | H8: PASS 18/18 ; 4 V99 + 7 oracle + 4 SSR + 3 revue | I8: PASS_PRODUCTION 23/23 ; fixture préparée et contrôles natifs | J8: tests/homeworld-navigation-v99.test.mjs docs/homeworld-navigation-v99.md tests/homeworld-navigation-review-v99.test.mjs outputs/qa-three-modes-v99/production/result.json | K8: 18 tests modèle/SSR et 23 contrôles Chromium Homeworld validés : marche clavier réelle, Escalier du Conseil vers +1, pause/reprise, sauvegarde et Continuer. Froid 2 988 ms, chaud 210 ms, même worker, 18 points. Portée : fixture Homeworld préparée et horloge navigateur contrôlée, pas une campagne jouée ; publication suivie séparément. | L8: homeworld_v99
A9: EXCEL-V99-TRACE | B9: Classeurs | C9: Relier sources, code, preuve et reste à faire | D9: 5 classeurs locaux conservés ; suivi V63 comme base ; extraits source et exports runtime actuels | E9: scripts/build-excel-followup-v99.mjs scripts/build-excel-followup-v99.py docs/v99-workstreams-source.json | F9: VALIDE_CIBLE | G9: Nouveau classeur V99 et registre JSON ; générateur reproductible sans nouvelle dépendance. | H9: PASS 6/6 ; revue OOXML indépendante PASS | I9: SANS_OBJET | J9: tests/excel-followup-v99.test.mjs docs/v99-excel-followup-qa.json | K9: 15 onglets dont 5 feuilles V63 conservées, 12 compteurs recomptés, textes source littéraux et génération déterministe vérifiés. Lecture indépendante openpyxl ; aucune application Excel/LibreOffice native disponible. | L9: excel_v99
A10: CLANS-PLANETES-30 | B10: Guerre de clans | C10: 30 théâtres et surfaces non jouables | D10: Créations originales du projet V96/V97 ; Korthas reprend ses noms et règles V3 | E10: app/game/systems/clanWarPlanetsV96.ts app/game/systems/clanWarCoastlinesV97.ts | F10: LIVRE_PARTIEL | G10: 30 mondes, dont classiques et exotiques ; contours continentaux, routes et couleurs de contrôle dans l'atlas. | H10: HISTORIQUE_V98 | I10: HISTORIQUE_V98 | J10: docs/integration-v98.md outputs/qa-three-modes-v98/verification.json | K10: Préserver l'accès par routes courtes ; aucun statut de planète canonique 1:1 attribué aux créations originales. Validation V99 séparée. | L10: clans_v99
A11: CLANS-COMMANDEMENT-V98 | B11: Guerre de clans | C11: Front, ordres et inspection sans fuite adverse | D11: Adaptation du projet de l'atlas V95–V98 | E11: app/game/systems/clanWarCommandV98.ts app/game/ClanWarCommandV98.tsx | F11: LIVRE_PARTIEL | G11: État d'un front connu et aperçu d'un ordre valide ; ressources localisées selon le mode. | H11: HISTORIQUE_V98 | I11: HISTORIQUE_V98 | J11: docs/integration-v98.md | K11: La preuve V98 reste historique ; ne pas déclarer terminés les trois modes et toutes les règles du classeur. | L11: clans_v99
A12: V6-OUVRAGES-18 | B12: Guerre de clans | C12: Ouvrages V6 : vérifier chaque ligne source | D12: V6, Structures de guerre, W3-S01 à W3-S18, lignes 6 à 23 | E12: app/game/systems/clanWarWorksV6.ts app/game/systems/clanWarMedicalV92.ts | F12: LIVRE_PARTIEL | G12: 12 définitions acceptées par l'export actuel ; standalone. Les six autres restent explicitement ouvertes dans OuvragesV6. | H12: HISTORIQUE_V92 | I12: A_VALIDER | J12: docs/clan-war-medical-v92.md docs/clan-war-structures-v89.md | K12: S09, S10, S13, S14, S15, S18 : transport, montures, énergie, duel, sons et route orbitale à raccorder. Le suivi V88 à 8/18 reste historique. | L12: clans_v99
A13: V6-LOGISTIQUE-CAMPAGNE | B13: Guerre de clans | C13: Raccorder les exercices à la campagne persistante | D13: docs/yautja-v88-import-and-excel-status.md ; séparation V3/V6 documentée en V85 | E13: app/game/systems/clanWarBibleV6.ts app/game/systems/clanWarWorksV6.ts | F13: OUVERT | G13: Les démonstrations identifiées fonctionnent dans leur contexte libre. | H13: NON_EXECUTE | I13: NON_EXECUTE | J13: docs/release-v85-imports-and-excel.md docs/yautja-v88-import-and-excel-status.md | K13: Arrivée effective, mandat, ravitaillement et sauvegarde persistante de campagne ; pas de conversion automatique des monnaies et identifiants V3/V6. | L13: integration
A14: PRESERVE-EXPANSION-80 | B14: Preserve Hunt | C14: Étendre les secteurs et les combattants | D14: docs/v66-game-reserve-delivery.md et docs/v98-preserve-hunt-interceptions.md | E14: app/game/systems/gameReserveV66.ts | F14: OUVERT | G14: Premier terrain Vharuun : 3 secteurs / 80 visés, 8 combattants / 100 visés. | H14: HISTORIQUE_V98 | I14: HISTORIQUE_V98 | J14: docs/integration-v98.md | K14: Créer, intégrer et jouer chaque secteur et combattant supplémentaire ; un plan, une liste ou une image n'est pas un terrain jouable. | L14: preserve_v99
A15: HOMEWORLD-GUIDAGE-V98 | B15: Homeworld | C15: Parcourir les six étages et reprendre le guidage | D15: docs/homeworld-wayfinding-v98.md | E15: app/game/systems/homeworldWayfindingV98.ts | F15: LIVRE_PARTIEL | G15: Parcours V98 joué du port aux escaliers du Conseil, guide annulable, reprise après rechargement. | H15: HISTORIQUE_V98 | I15: HISTORIQUE_V98 | J15: docs/integration-v98.md docs/homeworld-wayfinding-v98.md | K15: Mesurer et rejouer V99 ; ne pas transformer une route calculée en preuve de toutes les interactions du Homeworld. | L15: homeworld_v99
... A18: V6-NAVIRE-VOYAGE | B18: Navire | C18: Passer de l'inspection au voyage réel | D18: V6 navire : R2-M021 acquisition, R2-M022 préparation, R2-M023 voyage ; corpus de 19 feuilles | E18: public/game/dialogues/v85/bible-ships.json | F18: OUVERT | G18: Huit postes d'inspection documentaire décrits en V88 ; aucun navire acquis par leur consultation. | H18: HISTORIQUE_V88 | I18: A_VALIDER | J18: docs/yautja-v88-import-and-excel-status.md | K18: Jouer acquisition, préparation, manifestes et route orbitale avant toute arrivée ; l'interface ne constitue pas un voyage. | L18: integration
A19: V84-VARIANTES-640 | B19: Graphismes | C19: Raccorder les variantes de PNJ et leurs images | D19: Suivi des imports V84/V85/V88 | F19: OUVERT | G19: 640 variantes V84 documentées comme métadonnées ; pas de PNG fourni par ce registre. | H19: NON_EXECUTE | I19: NON_EXECUTE | J19: docs/yautja-v88-import-and-excel-status.md | K19: Produire et vérifier les images natives puis leurs animations et intégrations ; une référence artistique reste une référence. | L19: art
A20: V86-GARNISONS-72-PNG | B20: Graphismes | C20: Distinguer corps statiques et kits animés | D20: docs/release-v86-excel-and-garrisons.md : 18 groupes / 72 PNG natifs | F20: LIVRE_PARTIEL | G20: Corps statiques documentés ; ce nombre ne valide ni toutes les animations ni une fidélité canonique 1:1. | H20: HISTORIQUE_V86 | I20: A_VALIDER | J20: docs/release-v86-excel-and-garrisons.md | K20: Auditer et intégrer les gestes requis dans leur contexte ; aucune clôture générale des kits à partir d'un idle. | L20: art
A21: PIT-V54-6-IDENTITES | B21: The Pit | C21: Conserver les six identités ou incarnations ouvertes | D21: Classeur V54 : 02_PERSONNAGES lignes 200 à 205 ; réconciliation V63 | E21: docs/v63-workbook-roster-audit.json | F21: OUVERT | G21: Six dossiers historiques ouverts, détaillés dans PitOuvertV99 ; le nombre de combattants runtime est compté séparément. | H21: HISTORIQUE_V63 | I21: NON_EXECUTE | J21: docs/v63-workbook-roster-audit.md docs/v63-workbook-roster-audit.json | K21: Identifier et sourcer chaque apparence, produire son kit puis la jouer ; ne pas certifier un kit complet depuis des variantes idle. | L21: pit
A22: PIT-V54-522-EVENEMENTS | B22: The Pit | C22: Rouvrir les événements avec leurs cellules exactes | D22: 174 dossiers / 522 descriptions de 10_VIE_DES_STAGES, réconciliation historique V63 | E22: docs/v63-stage-open-work.json | F22: OUVERT | G22: Les 522 descriptions et leur statut V63 sont reprises sans certifier tous les décors actuels. | H22: HISTORIQUE_V63 | I22: NON_EXECUTE | J22: docs/v63-stage-open-work.json docs/v63-followup-workbook-qa.json | K22: Recertifier sources, déclencheurs et conditions ; l'absence d'un registre V60–V63 ne prouve pas l'absence d'une animation legacy. | L22: pit
A23: PIT-ST103-GOLGOTHA | B23: The Pit | C23: Trio distinct de Golgotha encore ouvert | D23: 10_VIE_DES_STAGES!E311:E313 ; ST103, arena-187-golgotha-uscm-airlock | E23: docs/v63-stage-open-work.json | F23: OUVERT | G23: Adaptations V63 d'un autre dossier conservées ; ce trio distinct n'est pas livré par leur présence. | H23: HISTORIQUE_V63 | I23: NON_EXECUTE | J23: docs/v63-stage-open-work.json | K23: Vérifier la présence dans la scène primaire pour E313 avant toute silhouette et traiter séparément les trois événements. | L23: pit
A24: PIT-ST020-EVACUATION | B24: The Pit | C24: Évacuation hors du toit et chronologie de Wolf | D24: 10_VIE_DES_STAGES!E62 ; ST020, arena-126-avpr-2007-hospital-roof | E24: docs/v63-stage-open-work.json | F24: OUVERT | G24: Sprite conservé mais inactif sur le toit, où il contredit E505. | H24: HISTORIQUE_V63 | I24: NON_EXECUTE | J24: docs/v63-stage-open-work.json | K24: Trouver une continuité narrative ou hors toit vérifiée ; équipement et chronologie de Wolf toujours ouverts. | L24: pit

Sheet SourcesV99
A1: Inventaire des classeurs et des originaux manquants
A2: Empreinte du fichier local pour les présents ; empreinte de la source identifiée pour les originaux absents.
A3: Synthèse : SyntheseV99 · filtres ligne 4 · en-têtes figés
A4: Classeur | B4: Disponibilité | C4: Fichier local / extractions disponibles | D4: SHA-256 | E4: Feuilles présentes | F4: Contenu / portée | G4: Limite
A5: catalogue_yautja_tous_medias.xlsx | B5: PRESENT_CONSERVE | C5: art-source/v6/catalogue/catalogue_yautja_tous_medias.xlsx | D5: 6b696cabe94f0821f4bc02a1587ca5782789ffcc58ad52339626cc173515e68e | E5: 12 | F5: Synthèse ; Index maître ; Films & animation ; Jeux vidéo ; Comics & romans ; Kenner ; NECA ; Fan-films ; Alias & doublons ; Clans & classes ; Exclusions ; Sources | G5: Original local conservé sans réécriture ; les cinq feuilles du V63 sont aussi présentes dans le nouveau suivi.
A6: THE_PIT_STAGES_V60_SUIVI.xlsx | B6: PRESENT_CONSERVE | C6: docs/THE_PIT_STAGES_V60_SUIVI.xlsx | D6: d1ef8866b4cd94e5e90130efe8ed62a6c099dc0093215bd17348ff25c946ef04 | E6: 2 | F6: Stages ; Animations | G6: Original local conservé sans réécriture ; les cinq feuilles du V63 sont aussi présentes dans le nouveau suivi.
A7: THE_PIT_STAGES_V61_SUIVI.xlsx | B7: PRESENT_CONSERVE | C7: docs/THE_PIT_STAGES_V61_SUIVI.xlsx | D7: 5dd113dfb7cb40f3517ba4f1081bd1ece977a9fba3e9cedc01de87835effd2e6 | E7: 2 | F7: AnimationsV61 ; Resteclasseur | G7: Original local conservé sans réécriture ; les cinq feuilles du V63 sont aussi présentes dans le nouveau suivi.
A8: THE_PIT_V62_SUIVI.xlsx | B8: PRESENT_CONSERVE | C8: docs/THE_PIT_V62_SUIVI.xlsx | D8: c7c9986d872faf0cbc8398e697a28b9eae57328989fb09eed2881c431c1b57bb | E8: 3 | F8: LotV62 ; CombattantsV54 ; Resteclasseur | G8: Original local conservé sans réécriture ; les cinq feuilles du V63 sont aussi présentes dans le nouveau suivi.
A9: THE_PIT_V63_SUIVI.xlsx | B9: PRESENT_CONSERVE | C9: docs/THE_PIT_V63_SUIVI.xlsx | D9: 192b168456091239e65939b99c4630de791cfaca4f33f61a1c6a8a032fc9c7af | E9: 5 | F9: LotV62 ; CombattantsV54 ; Resteclasseur ; LotV63 ; StagesV54 | G9: Original local conservé sans réécriture ; les cinq feuilles du V63 sont aussi présentes dans le nouveau suivi.
A10: Yautja_V6_Bible_Cumulative_et_Dialogues.xlsx | B10: ORIGINAL_MANQUANT | C10: app/game/clanWarBibleV6Source.json public/game/dialogues/v85/bible-dialogues.json public/game/dialogues/v85/bible-ships.json | D10: 87ad5d1a6eaf49f2908a4457ef3f97b8f34db481a24bbc121d2e924559b19183 | F10: Original privé absent ; extractions de guerre, dialogues et navire présentes. Les 139 feuilles du classeur ne sont pas 139 fonctions livrées. | G10: Les extractions ne remplacent pas le fichier privé original ; aucun chemin privé utilisateur n’est reproduit.
A11: Yautja_V3_Guerres_de_Clans_Trois_Modes.xlsx | B11: ORIGINAL_MANQUANT | C11: app/game/clanWarV85Source.json | D11: 3ef3712c9ffa865f918133bee7667155c1bb320f060b4a19cc58ff650ffd0dfa | F11: Original privé absent ; extraction de 39 feuilles / 679 fiches conservée. Aucun solde V6 ni identifiant W3 n'est confondu avec le modèle V3. | G11: Les extractions ne remplacent pas le fichier privé original ; aucun chemin privé utilisateur n’est reproduit.
A12: Classeur source THE PIT V54 | B12: ORIGINAL_MANQUANT | C12: docs/v63-workbook-roster-audit.json docs/v63-stage-open-work.json | D12: 32f2ee8e4fd801e7ca677a54862f2bd0123a2e78d12c015f64b50ab28184c380 | F12: Original privé absent ; réconciliations historiques V63 disponibles, non recertifiées comme livraison intégrale V99. | G12: Les extractions ne remplacent pas le fichier privé original ; aucun chemin privé utilisateur n’est reproduit.

Sheet PlanetesV99
A1: 30 planètes · données des cartes réellement exportées
A2: Continents physiques ≠ régions administratives. Les couleurs de surface ne sont pas celles du contrôle des clans.
A3: Synthèse : SyntheseV99 · filtres ligne 4 · en-têtes figés
A4: ID | B4: Planète | C4: Famille | D4: Biome terrestre | E4: Surface non jouable | F4: Texture | G4: Couleur de fond | H4: Couleur de détail | I4: Continents | J4: Régions | K4: Territoires | L4: Terres (%) | M4: Routes | N4: Graphe connecté | O4: Écart côtes interrégion max (°) | P4: Provenance / fidélité
A5: korthas | B5: Korthas | C5: classic | D5: temperate | E5: Mers de cobalt | F5: water | G5: #164e6d | H5: #4f9cac | I5: 5 | J5: 6 | K5: 36 | L5: 60.76 | M5: 70 | N5: TRUE | O5: 19.5 | P5: Noms et règles V3 ; géographie originale V96/V97
A6: thalassa | B6: Thalassa | C6: classic | D6: jungle | E6: Lagons turquoise | F6: water | G6: #177e8b | H6: #61dfd1 | I6: 3 | J6: 6 | K6: 36 | L6: 57.41 | M6: 58 | N6: TRUE | O6: 19.5 | P6: Carte originale du projet ; pas une planète canonique certifiée
A7: vitriol | B7: Vitriol | C7: exotic | D7: swamp | E7: Acide émeraude | F7: acid | G7: #628d25 | H7: #c6ef43 | I7: 4 | J7: 6 | K7: 36 | L7: 58 | M7: 54 | N7: TRUE | O7: 19.5 | P7: Carte originale du projet ; pas une planète canonique certifiée
A8: nivalis | B8: Nivalis | C8: classic | D8: snow | E8: Banquise azurée | F8: ice | G8: #73aabd | H8: #bceaf3 | I8: 6 | J8: 6 | K8: 36 | L8: 49.46 | M8: 35 | N8: TRUE | O8: 3.87 | P8: Carte originale du projet ; pas une planète canonique certifiée
A9: serak | B9: Serak | C9: classic | D9: desert | E9: Mers de dunes ocre | F9: sand | G9: #ad773f | H9: #e6b66b | I9: 2 | J9: 6 | K9: 36 | L9: 62.72 | M9: 58 | N9: TRUE | O9: 17.53 | P9: Carte originale du projet ; pas une planète canonique certifiée
A10: pyroclaste | B10: Pyroclaste | C10: classic | D10: volcanic | E10: Lave incandescente | F10: lava | G10: #8a3021 | H10: #ff8d39 | I10: 2 | J10: 6 | K10: 36 | L10: 65.83 | M10: 59 | N10: TRUE | O10: 19.5 | P10: Carte originale du projet ; pas une planète canonique certifiée
A11: halycon | B11: Halycon | C11: classic | D11: salt | E11: Saumure rose | F11: brine | G11: #a65883 | H11: #ef9cc1 | I11: 4 | J11: 6 | K11: 36 | L11: 53.78 | M11: 52 | N11: TRUE | O11: 19.5 | P11: Carte originale du projet ; pas une planète canonique certifiée
A12: uranth | B12: Uranth | C12: exotic | D12: irradiated | E12: Nappes radioactives | F12: radioactive | G12: #467b2b | H12: #a7ff38 | I12: 4 | J12: 6 | K12: 36 | L12: 59.06 | M12: 45 | N12: TRUE | O12: 11.99 | P12: Carte originale du projet ; pas une planète canonique certifiée
A13: amethys | B13: Améthys | C13: exotic | D13: crystal | E13: Océan de cristaux violets | F13: crystal | G13: #6e438d | H13: #be90ec | I13: 6 | J13: 6 | K13: 36 | L13: 54.77 | M13: 43 | N13: TRUE | O13: 19.5 | P13: Carte originale du projet ; pas une planète canonique certifiée
A14: mycelia | B14: Mycélia | C14: exotic | D14: fungal | E14: Nappes de spores | F14: spores | G14: #4e6176 | H14: #b9d788 | I14: 4 | J14: 6 | K14: 36 | L14: 60.25 | M14: 59 | N14: TRUE | O14: 19.5 | P14: Carte originale du projet ; pas une planète canonique certifiée
A15: nebulis | B15: Nébulis | C15: classic | D15: mountain | E15: Brume des vallées | F15: mist | G15: #768991 | H15: #adbfc1 | I15: 4 | J15: 6 | K15: 36 | L15: 60.95 | M15: 52 | N15: TRUE | O15: 19.5 | P15: Carte originale du projet ; pas une planète canonique certifiée
A16: abyssia | B16: Abyssia | C16: classic | D16: ocean | E16: Fosses indigo | F16: water | G16: #293f83 | H16: #6a80da | I16: 6 | J16: 6 | K16: 36 | L16: 51.24 | M16: 40 | N16: TRUE | O16: 19.5 | P16: Carte originale du projet ; pas une planète canonique certifiée
... A34: nyctera | B34: Nyctéra | C34: exotic | D34: fungal | E34: Spores violettes | F34: spores | G34: #68517f | H34: #b39ed6 | I34: 6 | J34: 6 | K34: 36 | L34: 55.19 | M34: 59 | N34: TRUE | O34: 19.46 | P34: Carte originale du projet ; pas une planète canonique certifiée

Sheet OuvragesV6
A1: 18 ouvrages V6 · état de consommation ligne par ligne
A2: Le nombre actuel 12/18 ne réécrit pas le suivi historique V88 à 8/18. Le contexte libre reste distinct de la campagne.
A3: Synthèse : SyntheseV99 · filtres ligne 4 · en-têtes figés
A4: ID source | B4: Ouvrage | C4: Feuille | D4: Ligne | E4: Cellules source | F4: État runtime | G4: Adaptateur | H4: Coût RAV | I4: Délai tours | J4: Opérateur source | K4: Périmètre / reste | L4: SHA-256 source V6
A5: W3-S01 | B5: Poste de veille | C5: Structures de guerre | D5: 6 | E5: C6, D6, E6, F6, G6, H6, I6, J6, K6 | F5: INTEGRE_LIBRE | G5: watch | H5: 6 | I5: 2 | J5: W3-U02 | K5: Définition acceptée par le runtime libre actuel ; raccord campagne et certification globale non déduits. | L5: 87ad5d1a6eaf49f2908a4457ef3f97b8f34db481a24bbc121d2e924559b19183
A6: W3-S02 | B6: Abri de relève | C6: Structures de guerre | D6: 7 | E6: C7, D7, E7, F7, G7, H7, I7, J7, K7 | F6: INTEGRE_LIBRE | G6: rest | H6: 8 | I6: 2 | J6: W3-U17 | K6: Définition acceptée par le runtime libre actuel ; raccord campagne et certification globale non déduits. | L6: 87ad5d1a6eaf49f2908a4457ef3f97b8f34db481a24bbc121d2e924559b19183
A7: W3-S03 | B7: Cache logistique | C7: Structures de guerre | D7: 8 | E7: C8, D8, E8, F8, G8, H8, I8, J8, K8 | F7: INTEGRE_LIBRE | G7: stock | H7: 10 | I7: 2 | J7: W3-U19 | K7: Définition acceptée par le runtime libre actuel ; raccord campagne et certification globale non déduits. | L7: 87ad5d1a6eaf49f2908a4457ef3f97b8f34db481a24bbc121d2e924559b19183
A8: W3-S04 | B8: Atelier d’ancrage | C8: Structures de guerre | D8: 9 | E8: C9, D9, E9, F9, G9, H9, I9, J9, K9 | F8: INTEGRE_LIBRE | G8: repair | H8: 12 | I8: 2 | J8: W3-U20 | K8: Définition acceptée par le runtime libre actuel ; raccord campagne et certification globale non déduits. | L8: 87ad5d1a6eaf49f2908a4457ef3f97b8f34db481a24bbc121d2e924559b19183
A9: W3-S05 | B9: Balise de route | C9: Structures de guerre | D9: 10 | E9: C10, D10, E10, F10, G10, H10, I10, J10, K10 | F9: INTEGRE_LIBRE | G9: navigation | H9: 4 | I9: 2 | J9: W3-U06 | K9: Définition acceptée par le runtime libre actuel ; raccord campagne et certification globale non déduits. | L9: 87ad5d1a6eaf49f2908a4457ef3f97b8f34db481a24bbc121d2e924559b19183
A10: W3-S06 | B10: Plateforme de tir | C10: Structures de guerre | D10: 11 | E10: C11, D11, E11, F11, G11, H11, I11, J11, K11 | F10: INTEGRE_LIBRE | G10: platform | H10: 10 | I10: 2 | J10: W3-U13 | K10: Définition acceptée par le runtime libre actuel ; raccord campagne et certification globale non déduits. | L10: 87ad5d1a6eaf49f2908a4457ef3f97b8f34db481a24bbc121d2e924559b19183
A11: W3-S07 | B11: Seuil renforcé | C11: Structures de guerre | D11: 12 | E11: C12, D12, E12, F12, G12, H12, I12, J12, K12 | F11: INTEGRE_LIBRE | G11: defense | H11: 12 | I11: 2 | J11: W3-U07 | K11: Définition acceptée par le runtime libre actuel ; raccord campagne et certification globale non déduits. | L11: 87ad5d1a6eaf49f2908a4457ef3f97b8f34db481a24bbc121d2e924559b19183
A12: W3-S08 | B12: Pont de cordes | C12: Structures de guerre | D12: 13 | E12: C13, D13, E13, F13, G13, H13, I13, J13, K13 | F12: INTEGRE_LIBRE | G12: bridge | H12: 14 | I12: 3 | J12: W3-U12 | K12: Définition acceptée par le runtime libre actuel ; raccord campagne et certification globale non déduits. | L12: 87ad5d1a6eaf49f2908a4457ef3f97b8f34db481a24bbc121d2e924559b19183
A13: W3-S09 | B13: Quai léger | C13: Structures de guerre | D13: 14 | E13: C14, D14, E14, F14, G14, H14, I14, J14, K14 | F13: OUVERT | K13: Raccorder un quai à une rive praticable et à un transport réellement identifié ; pas de téléportation de cargaison. | L13: 87ad5d1a6eaf49f2908a4457ef3f97b8f34db481a24bbc121d2e924559b19183
A14: W3-S10 | B14: Aire de montures | C14: Structures de guerre | D14: 15 | E14: C15, D15, E15, F15, G15, H15, I15, J15, K15 | F14: OUVERT | K14: Identifier et déplacer les montures existantes, leurs gardiens et leur capacité ; ne pas créer une monture depuis un compteur. | L14: 87ad5d1a6eaf49f2908a4457ef3f97b8f34db481a24bbc121d2e924559b19183
A15: W3-S11 | B15: Poste de soin | C15: Structures de guerre | D15: 16 | E15: C16, D16, E16, F16, G16, H16, I16, J16, K16 | F15: INTEGRE_LIBRE | G15: medical | H15: 14 | I15: 3 | J15: W3-U18 | K15: Définition acceptée par le runtime libre actuel ; raccord campagne et certification globale non déduits. | L15: 87ad5d1a6eaf49f2908a4457ef3f97b8f34db481a24bbc121d2e924559b19183
A16: W3-S12 | B16: Relais de signaux | C16: Structures de guerre | D16: 17 | E16: C17, D17, E17, F17, G17, H17, I17, J17, K17 | F16: INTEGRE_LIBRE | G16: relay | H16: 12 | I16: 2 | J16: W3-U28 | K16: Définition acceptée par le runtime libre actuel ; raccord campagne et certification globale non déduits. | L16: 87ad5d1a6eaf49f2908a4457ef3f97b8f34db481a24bbc121d2e924559b19183
A17: W3-S13 | B17: Écran de confinement | C17: Structures de guerre | D17: 18 | E17: C18, D18, E18, F18, G18, H18, I18, J18, K18 | F17: OUVERT | K17: Raccorder l'alimentation et le coût réel de confinement ; aucun effet gratuit déduit de la description. | L17: 87ad5d1a6eaf49f2908a4457ef3f97b8f34db481a24bbc121d2e924559b19183
A18: W3-S14 | B18: Emplacement de duel | C18: Structures de guerre | D18: 19 | E18: C19, D19, E19, F19, G19, H19, I19, J19, K19 | F18: OUVERT | K18: Raccorder un duel accepté par ses participants et son résultat réel ; pas de victoire automatique. | L18: 87ad5d1a6eaf49f2908a4457ef3f97b8f34db481a24bbc121d2e924559b19183
A19: W3-S15 | B19: Station d’écoute | C19: Structures de guerre | D19: 20 | E19: C20, D20, E20, F20, G20, H20, I20, J20, K20 | F19: OUVERT | K19: Raccorder des sons enregistrés et situés, leur portée et leur occultation ; une direction de voix écrite n'est pas un son. | L19: 87ad5d1a6eaf49f2908a4457ef3f97b8f34db481a24bbc121d2e924559b19183
A20: W3-S16 | B20: Dépôt de retour | C20: Structures de guerre | D20: 21 | E20: C21, D21, E21, F21, G21, H21, I21, J21, K21 | F20: INTEGRE_LIBRE | G20: extraction | H20: 14 | I20: 3 | J20: W3-U17 | K20: Définition acceptée par le runtime libre actuel ; raccord campagne et certification globale non déduits. | L20: 87ad5d1a6eaf49f2908a4457ef3f97b8f34db481a24bbc121d2e924559b19183
A21: W3-S17 | B21: Anneau de treuils | C21: Structures de guerre | D21: 22 | E21: C22, D22, E22, F22, G22, H22, I22, J22, K22 | F21: INTEGRE_LIBRE | G21: hoist | H21: 16 | I21: 3 | J21: W3-U20 | K21: Définition acceptée par le runtime libre actuel ; raccord campagne et certification globale non déduits. | L21: 87ad5d1a6eaf49f2908a4457ef3f97b8f34db481a24bbc121d2e924559b19183
A22: W3-S18 | B22: Plateforme d’escale | C22: Structures de guerre | D22: 23 | E22: C23, D23, E23, F23, G23, H23, I23, J23, K23 | F22: OUVERT | K22: Raccorder un navire acquis et une route orbitale effective ; l'inspection documentaire ne donne ni navire ni voyage. | L22: 87ad5d1a6eaf49f2908a4457ef3f97b8f34db481a24bbc121d2e924559b19183

Sheet PitOuvertV99
A1: The Pit · six dossiers personnages laissés ouverts
A2: Réconciliation V63 reprise avec ses cellules et limites ; les kits et identités ne sont pas recertifiés par le suivi V99.
A3: Synthèse : SyntheseV99 · filtres ligne 4 · en-têtes figés
